2021-05-16 15:45:37,442 ERROR: Exception on /edit_profile/ [POST] [in C:\Users\15016\AppData\Local\Programs\Python\Python37\lib\site-packages\flask\app.py:1892]
Traceback (most recent call last):
  File "C:\Users\15016\AppData\Local\Programs\Python\Python37\lib\site-packages\sqlalchemy\engine\base.py", line 1277, in _execute_context
    cursor, statement, parameters, context
  File "C:\Users\15016\AppData\Local\Programs\Python\Python37\lib\site-packages\sqlalchemy\engine\default.py", line 593, in do_execute
    cursor.execute(statement, parameters)
  File "C:\Users\15016\AppData\Local\Programs\Python\Python37\lib\site-packages\pymysql\cursors.py", line 163, in execute
    result = self._query(query)
  File "C:\Users\15016\AppData\Local\Programs\Python\Python37\lib\site-packages\pymysql\cursors.py", line 321, in _query
    conn.query(q)
  File "C:\Users\15016\AppData\Local\Programs\Python\Python37\lib\site-packages\pymysql\connections.py", line 505, in query
    self._affected_rows = self._read_query_result(unbuffered=unbuffered)
  File "C:\Users\15016\AppData\Local\Programs\Python\Python37\lib\site-packages\pymysql\connections.py", line 724, in _read_query_result
    result.read()
  File "C:\Users\15016\AppData\Local\Programs\Python\Python37\lib\site-packages\pymysql\connections.py", line 1069, in read
    first_packet = self.connection._read_packet()
  File "C:\Users\15016\AppData\Local\Programs\Python\Python37\lib\site-packages\pymysql\connections.py", line 676, in _read_packet
    packet.raise_for_error()
  File "C:\Users\15016\AppData\Local\Programs\Python\Python37\lib\site-packages\pymysql\protocol.py", line 223, in raise_for_error
    err.raise_mysql_exception(self._data)
  File "C:\Users\15016\AppData\Local\Programs\Python\Python37\lib\site-packages\pymysql\err.py", line 107, in raise_mysql_exception
    raise errorclass(errno, errval)
pymysql.err.IntegrityError: (1062, "Duplicate entry 'susan' for key 'ix_user_username'")

The above exception was the direct cause of the following exception:

Traceback (most recent call last):
  File "C:\Users\15016\AppData\Local\Programs\Python\Python37\lib\site-packages\flask\app.py", line 2447, in wsgi_app
    response = self.full_dispatch_request()
  File "C:\Users\15016\AppData\Local\Programs\Python\Python37\lib\site-packages\flask\app.py", line 1952, in full_dispatch_request
    rv = self.handle_user_exception(e)
  File "C:\Users\15016\AppData\Local\Programs\Python\Python37\lib\site-packages\flask\app.py", line 1821, in handle_user_exception
    reraise(exc_type, exc_value, tb)
  File "C:\Users\15016\AppData\Local\Programs\Python\Python37\lib\site-packages\flask\_compat.py", line 39, in reraise
    raise value
  File "C:\Users\15016\AppData\Local\Programs\Python\Python37\lib\site-packages\flask\app.py", line 1950, in full_dispatch_request
    rv = self.dispatch_request()
  File "C:\Users\15016\AppData\Local\Programs\Python\Python37\lib\site-packages\flask\app.py", line 1936, in dispatch_request
    return self.view_functions[rule.endpoint](**req.view_args)
  File "C:\Users\15016\AppData\Local\Programs\Python\Python37\lib\site-packages\flask_login\utils.py", line 272, in decorated_view
    return func(*args, **kwargs)
  File "E:\工作项目\lgdgrzx_web_v1_flask\myapp\views\routes.py", line 98, in edit_profile
    db.session.commit()
  File "C:\Users\15016\AppData\Local\Programs\Python\Python37\lib\site-packages\sqlalchemy\orm\scoping.py", line 163, in do
    return getattr(self.registry(), name)(*args, **kwargs)
  File "C:\Users\15016\AppData\Local\Programs\Python\Python37\lib\site-packages\sqlalchemy\orm\session.py", line 1042, in commit
    self.transaction.commit()
  File "C:\Users\15016\AppData\Local\Programs\Python\Python37\lib\site-packages\sqlalchemy\orm\session.py", line 504, in commit
    self._prepare_impl()
  File "C:\Users\15016\AppData\Local\Programs\Python\Python37\lib\site-packages\sqlalchemy\orm\session.py", line 483, in _prepare_impl
    self.session.flush()
  File "C:\Users\15016\AppData\Local\Programs\Python\Python37\lib\site-packages\sqlalchemy\orm\session.py", line 2536, in flush
    self._flush(objects)
  File "C:\Users\15016\AppData\Local\Programs\Python\Python37\lib\site-packages\sqlalchemy\orm\session.py", line 2678, in _flush
    transaction.rollback(_capture_exception=True)
  File "C:\Users\15016\AppData\Local\Programs\Python\Python37\lib\site-packages\sqlalchemy\util\langhelpers.py", line 70, in __exit__
    with_traceback=exc_tb,
  File "C:\Users\15016\AppData\Local\Programs\Python\Python37\lib\site-packages\sqlalchemy\util\compat.py", line 182, in raise_
    raise exception
  File "C:\Users\15016\AppData\Local\Programs\Python\Python37\lib\site-packages\sqlalchemy\orm\session.py", line 2638, in _flush
    flush_context.execute()
  File "C:\Users\15016\AppData\Local\Programs\Python\Python37\lib\site-packages\sqlalchemy\orm\unitofwork.py", line 422, in execute
    rec.execute(self)
  File "C:\Users\15016\AppData\Local\Programs\Python\Python37\lib\site-packages\sqlalchemy\orm\unitofwork.py", line 589, in execute
    uow,
  File "C:\Users\15016\AppData\Local\Programs\Python\Python37\lib\site-packages\sqlalchemy\orm\persistence.py", line 236, in save_obj
    update,
  File "C:\Users\15016\AppData\Local\Programs\Python\Python37\lib\site-packages\sqlalchemy\orm\persistence.py", line 995, in _emit_update_statements
    statement, multiparams
  File "C:\Users\15016\AppData\Local\Programs\Python\Python37\lib\site-packages\sqlalchemy\engine\base.py", line 1011, in execute
    return meth(self, multiparams, params)
  File "C:\Users\15016\AppData\Local\Programs\Python\Python37\lib\site-packages\sqlalchemy\sql\elements.py", line 298, in _execute_on_connection
    return connection._execute_clauseelement(self, multiparams, params)
  File "C:\Users\15016\AppData\Local\Programs\Python\Python37\lib\site-packages\sqlalchemy\engine\base.py", line 1130, in _execute_clauseelement
    distilled_params,
  File "C:\Users\15016\AppData\Local\Programs\Python\Python37\lib\site-packages\sqlalchemy\engine\base.py", line 1317, in _execute_context
    e, statement, parameters, cursor, context
  File "C:\Users\15016\AppData\Local\Programs\Python\Python37\lib\site-packages\sqlalchemy\engine\base.py", line 1511, in _handle_dbapi_exception
    sqlalchemy_exception, with_traceback=exc_info[2], from_=e
  File "C:\Users\15016\AppData\Local\Programs\Python\Python37\lib\site-packages\sqlalchemy\util\compat.py", line 182, in raise_
    raise exception
  File "C:\Users\15016\AppData\Local\Programs\Python\Python37\lib\site-packages\sqlalchemy\engine\base.py", line 1277, in _execute_context
    cursor, statement, parameters, context
  File "C:\Users\15016\AppData\Local\Programs\Python\Python37\lib\site-packages\sqlalchemy\engine\default.py", line 593, in do_execute
    cursor.execute(statement, parameters)
  File "C:\Users\15016\AppData\Local\Programs\Python\Python37\lib\site-packages\pymysql\cursors.py", line 163, in execute
    result = self._query(query)
  File "C:\Users\15016\AppData\Local\Programs\Python\Python37\lib\site-packages\pymysql\cursors.py", line 321, in _query
    conn.query(q)
  File "C:\Users\15016\AppData\Local\Programs\Python\Python37\lib\site-packages\pymysql\connections.py", line 505, in query
    self._affected_rows = self._read_query_result(unbuffered=unbuffered)
  File "C:\Users\15016\AppData\Local\Programs\Python\Python37\lib\site-packages\pymysql\connections.py", line 724, in _read_query_result
    result.read()
  File "C:\Users\15016\AppData\Local\Programs\Python\Python37\lib\site-packages\pymysql\connections.py", line 1069, in read
    first_packet = self.connection._read_packet()
  File "C:\Users\15016\AppData\Local\Programs\Python\Python37\lib\site-packages\pymysql\connections.py", line 676, in _read_packet
    packet.raise_for_error()
  File "C:\Users\15016\AppData\Local\Programs\Python\Python37\lib\site-packages\pymysql\protocol.py", line 223, in raise_for_error
    err.raise_mysql_exception(self._data)
  File "C:\Users\15016\AppData\Local\Programs\Python\Python37\lib\site-packages\pymysql\err.py", line 107, in raise_mysql_exception
    raise errorclass(errno, errval)
sqlalchemy.exc.IntegrityError: (pymysql.err.IntegrityError) (1062, "Duplicate entry 'susan' for key 'ix_user_username'")
[SQL: UPDATE user SET username=%(username)s, about_me=%(about_me)s WHERE user.id = %(user_id)s]
[parameters: {'username': 'susan', 'about_me': "I'm the author of the Flask Mega-Tutorial you are now reading!", 'user_id': 4}]
(Background on this error at: http://sqlalche.me/e/13/gkpj)
2021-05-16 15:46:06,233 INFO: Microblog startup [in E:\工作项目\lgdgrzx_web_v1_flask\myapp\__init__.py:58]
2021-05-16 17:11:33,773 INFO: Microblog startup [in E:\工作项目\lgdgrzx_web_v1_flask\myapp\__init__.py:58]
2021-05-16 17:11:59,347 INFO: Microblog startup [in E:\工作项目\lgdgrzx_web_v1_flask\myapp\__init__.py:58]
2021-05-16 17:12:19,738 INFO: Microblog startup [in E:\工作项目\lgdgrzx_web_v1_flask\myapp\__init__.py:58]
2021-05-16 17:35:47,882 INFO: Microblog startup [in E:\工作项目\lgdgrzx_web_v1_flask\myapp\__init__.py:58]
2021-05-16 17:41:03,948 INFO: Microblog startup [in E:\工作项目\lgdgrzx_web_v1_flask\myapp\__init__.py:58]
2021-05-16 17:41:21,163 INFO: Microblog startup [in E:\工作项目\lgdgrzx_web_v1_flask\myapp\__init__.py:58]
2021-05-16 17:43:50,002 INFO: Microblog startup [in E:\工作项目\lgdgrzx_web_v1_flask\myapp\__init__.py:58]
